<!-- <?xml version="1.0"?> -->
<!-- =================================================================================== -->
<!-- |    This document was autogenerated by xacro from
/home/yangfan/workspace/zy_ws/robot_param_manager/a2-w/t3d0/basic/agibot/data/info/etc/body/basic/xacro/robot.xacro
| -->
<!-- |    EDITING THIS FILE BY HAND IS NOT RECOMMENDED                                 | -->
<!-- =================================================================================== -->
<robot name="raise_a2_w_t3">
  <!-- base, wheels, waists and head links and joints-->
  <link name="base_link">
    <inertial>
      <origin rpy="0.0 -0.0 0.0" xyz="-0.06828 -0.00428 0.45708" />
      <mass value="140.31" />
      <inertia ixx="53.80849" ixy="0.09217" ixz="-6.47504" iyy="55.02392" iyz="-0.16237"
        izz="6.16933" />
    </inertial>
    <visual>
      <geometry>
        <mesh filename="file:///mnt/nvme1n1p6/PLCT/NAV2/nav2_sim/src/robot_description/meshes/A2_W/base_link.STL"
          scale="1.0 1.0 1.0" />
      </geometry>
      <origin rpy="0.0 -0.0 0.0" xyz="0.0 0.0 0.0" />
      <material name="">
        <color rgba="0.8 0.4 0.0 1.0" />
        <texture filename="" />
      </material>
    </visual>
    <collision>
      <origin rpy="-0.0 0.0 -0.0"
        xyz="-2.1502376000015477e-05 -3.300607200001915e-05 0.13102241000000003" />
      <geometry>
        <box size="0.7819729 0.6368234 0.31247315" />
      </geometry>
    </collision>
    <collision>
      <origin rpy="-0.0 0.0 -0.0" xyz="-0.12920046 -0.00014732033000000588 0.29420674" />
      <geometry>
        <box size="0.44176495 0.41260087 0.07947397" />
      </geometry>
    </collision>
    <collision>
      <origin rpy="-0.0 0.0 -0.0" xyz="-0.17096134000000002 -0.00046768785000000923 0.9397358" />
      <geometry>
        <box size="0.3759756 0.38513064 1.2152664999999998" />
      </geometry>
    </collision>
  </link>
  <link name="wheel_1_yaw">
    <inertial>
      <origin rpy="0.0 -0.0 0.0" xyz="0.0 -0.05113 0.07968" />
      <mass value="1.13523" />
      <inertia ixx="0.01386" ixy="0.0" ixz="0.0" iyy="0.01038" iyz="-0.00383" izz="0.00457" />
    </inertial>
    <visual name="">
      <geometry>
        <mesh filename="file:///mnt/nvme1n1p6/PLCT/NAV2/nav2_sim/src/robot_description/meshes/A2_W/wheel_1_yaw.STL"
          scale="1.0 1.0 1.0" />
      </geometry>
      <origin rpy="0.0 -0.0 0.0" xyz="0.0 0.0 0.0" />
      <material name="">
        <color rgba="1.0 0.4 0.4 1.0" />
        <texture filename="" />
      </material>
    </visual>
  </link>
  <link name="wheel_1">
    <inertial>
      <origin rpy="0.0 -0.0 0.0" xyz="0.0 0.0 0.00212" />
      <mass value="7.15" />
      <inertia ixx="0.02719" ixy="1e-05" ixz="3e-05" iyy="0.02718" iyz="0.0" izz="0.04361" />
    </inertial>
    <visual name="">
      <geometry>
        <mesh filename="file:///mnt/nvme1n1p6/PLCT/NAV2/nav2_sim/src/robot_description/meshes/A2_W/wheel_1.STL" scale="1.0 1.0 1.0" />
      </geometry>
      <origin rpy="0.0 -0.0 0.0" xyz="0.0 0.0 0.0" />
      <material name="">
        <color rgba="1.0 0.4 0.4 1.0" />
        <texture filename="" />
      </material>
    </visual>

    <collision>
      <geometry>
        <mesh filename="file:///mnt/nvme1n1p6/PLCT/NAV2/nav2_sim/src/robot_description/meshes/A2_W/wheel_1.STL" scale="1.0 1.0 1.0" />
      </geometry>
      <origin rpy="0.0 -0.0 0.0" xyz="0.0 0.0 0.0" />
    </collision>


  </link>
  <link name="wheel_2_yaw">
    <inertial>
      <origin rpy="0.0 -0.0 0.0" xyz="-0.00341 0.06077 0.05854" />
      <mass value="2.21487" />
      <inertia ixx="0.02313" ixy="-0.00055" ixz="0.00065" iyy="0.01564" iyz="0.00677" izz="0.01154" />
    </inertial>
    <visual name="">
      <geometry>
        <mesh filename="file:///mnt/nvme1n1p6/PLCT/NAV2/nav2_sim/src/robot_description/meshes/A2_W/wheel_2_yaw.STL"
          scale="1.0 1.0 1.0" />
      </geometry>
      <origin rpy="0.0 -0.0 0.0" xyz="0.0 0.0 0.0" />
      <material name="">
        <color rgba="1.0 0.4 0.4 1.0" />
        <texture filename="" />
      </material>
    </visual>
  </link>
  <link name="wheel_2">
    <inertial>
      <origin rpy="0.0 -0.0 0.0" xyz="0.0 0.0 0.00212" />
      <mass value="7.15" />
      <inertia ixx="0.02719" ixy="1e-05" ixz="3e-05" iyy="0.02718" iyz="0.0" izz="0.04361" />
    </inertial>
    <visual name="">
      <geometry>
        <mesh filename="file:///mnt/nvme1n1p6/PLCT/NAV2/nav2_sim/src/robot_description/meshes/A2_W/wheel_2.STL" scale="1.0 1.0 1.0" />
      </geometry>
      <origin rpy="0.0 -0.0 0.0" xyz="0.0 0.0 0.0" />
      <material name="">
        <color rgba="1.0 0.4 0.4 1.0" />
        <texture filename="" />
      </material>
    </visual>
    <collision>
      <geometry>
        <mesh filename="file:///mnt/nvme1n1p6/PLCT/NAV2/nav2_sim/src/robot_description/meshes/A2_W/wheel_2.STL" scale="1.0 1.0 1.0" />
      </geometry>
      <origin rpy="0.0 -0.0 0.0" xyz="0.0 0.0 0.0" />
    </collision>

  </link>
  <link name="wheel_3_yaw">
    <inertial>
      <origin rpy="0.0 -0.0 0.0" xyz="-0.00339 -0.06083 0.05854" />
      <mass value="2.21487" />
      <inertia ixx="0.02315" ixy="0.00055" ixz="0.00065" iyy="0.01564" iyz="-0.00677" izz="0.01156" />
    </inertial>
    <visual name="">
      <geometry>
        <mesh filename="file:///mnt/nvme1n1p6/PLCT/NAV2/nav2_sim/src/robot_description/meshes/A2_W/wheel_3_yaw.STL"
          scale="1.0 1.0 1.0" />
      </geometry>
      <origin rpy="0.0 -0.0 0.0" xyz="0.0 0.0 0.0" />
      <material name="">
        <color rgba="1.0 0.4 0.4 1.0" />
        <texture filename="" />
      </material>
    </visual>
  </link>
  <link name="wheel_3">
    <inertial>
      <origin rpy="0.0 -0.0 0.0" xyz="0.0 0.0 0.00212" />
      <mass value="7.15" />
      <inertia ixx="0.02719" ixy="1e-05" ixz="3e-05" iyy="0.02718" iyz="0.0" izz="0.04361" />
    </inertial>
    <visual name="">
      <geometry>
        <mesh filename="file:///mnt/nvme1n1p6/PLCT/NAV2/nav2_sim/src/robot_description/meshes/A2_W/wheel_3.STL" scale="1.0 1.0 1.0" />
      </geometry>
      <origin rpy="0.0 -0.0 0.0" xyz="0.0 0.0 0.0" />
      <material name="">
        <color rgba="1.0 0.4 0.4 1.0" />
        <texture filename="" />
      </material>
    </visual>
    <collision>
      <geometry>
        <mesh filename="file:///mnt/nvme1n1p6/PLCT/NAV2/nav2_sim/src/robot_description/meshes/A2_W/wheel_3.STL" scale="1.0 1.0 1.0" />
      </geometry>
      <origin rpy="0.0 -0.0 0.0" xyz="0.0 0.0 0.0" />
    </collision>

  </link>
  <link name="wheel_4_yaw">
    <inertial>
      <origin rpy="0.0 -0.0 0.0" xyz="0.0 0.05113 0.07968" />
      <mass value="1.13523" />
      <inertia ixx="0.01386" ixy="0.0" ixz="0.0" iyy="0.01038" iyz="-0.00383" izz="0.00457" />
    </inertial>
    <visual name="">
      <geometry>
        <mesh filename="file:///mnt/nvme1n1p6/PLCT/NAV2/nav2_sim/src/robot_description/meshes/A2_W/wheel_4_yaw.STL"
          scale="1.0 1.0 1.0" />
      </geometry>
      <origin rpy="0.0 -0.0 0.0" xyz="0.0 0.0 0.0" />
      <material name="">
        <color rgba="1.0 0.4 0.4 1.0" />
        <texture filename="" />
      </material>
    </visual>
  </link>
  <link name="wheel_4">
    <inertial>
      <origin rpy="0.0 -0.0 0.0" xyz="0.0 0.0 0.00212" />
      <mass value="7.15" />
      <inertia ixx="0.02719" ixy="1e-05" ixz="3e-05" iyy="0.02718" iyz="0.0" izz="0.04361" />
    </inertial>
    <visual name="">
      <geometry>
        <mesh filename="file:///mnt/nvme1n1p6/PLCT/NAV2/nav2_sim/src/robot_description/meshes/A2_W/wheel_4.STL" scale="1.0 1.0 1.0" />
      </geometry>
      <origin rpy="0.0 -0.0 0.0" xyz="0.0 0.0 0.0" />
      <material name="">
        <color rgba="1.0 0.4 0.4 1.0" />
        <texture filename="" />
      </material>
    </visual>
    <collision>
      <geometry>
        <mesh filename="file:///mnt/nvme1n1p6/PLCT/NAV2/nav2_sim/src/robot_description/meshes/A2_W/wheel_4.STL" scale="1.0 1.0 1.0" />
      </geometry>
      <origin rpy="0.0 -0.0 0.0" xyz="0.0 0.0 0.0" />
    </collision>
  </link>
  <link name="body_link1">
    <inertial>
      <origin rpy="0.0 -0.0 0.0" xyz="0.01013 0.00012 0.01585" />
      <mass value="8.2325" />
      <inertia ixx="0.07424" ixy="-0.00093" ixz="0.00393" iyy="0.0608" iyz="-0.00045" izz="0.07605" />
    </inertial>
    <visual name="">
      <geometry>
        <mesh filename="file:///mnt/nvme1n1p6/PLCT/NAV2/nav2_sim/src/robot_description/meshes/A2_W/body_link1.STL"
          scale="1.0 1.0 1.0" />
      </geometry>
      <origin rpy="0.0 -0.0 0.0" xyz="0.0 0.0 0.0" />
      <material name="">
        <color rgba="0.8 0.4 0.0 1.0" />
      </material>
    </visual>
    <collision>
      <origin rpy="-0.0 0.0 -0.0" xyz="0.1406105 -0.0009894967000000088 0.012358501999999993" />
      <geometry>
        <box size="0.190643 0.297199 0.184147" />
      </geometry>
    </collision>
  </link>
  <link name="body_link2">
    <inertial>
      <origin rpy="0.0 -0.0 0.0" xyz="0.00286 -0.07903 -0.00469" />
      <mass value="13.65385" />
      <inertia ixx="0.36671" ixy="-0.01503" ixz="0.00027" iyy="0.04669" iyz="-0.00241" izz="0.37151" />
    </inertial>
    <visual name="">
      <geometry>
        <mesh filename="file:///mnt/nvme1n1p6/PLCT/NAV2/nav2_sim/src/robot_description/meshes/A2_W/body_link2.STL"
          scale="1.0 1.0 1.0" />
      </geometry>
      <origin rpy="0.0 -0.0 0.0" xyz="0.0 0.0 0.0" />
      <material name="">
        <color rgba="0.4 1.0 0.4 1.0" />
      </material>
    </visual>
    <collision>
      <origin rpy="-0.0 0.0 -0.0"
        xyz="0.006931330999999999 -0.16161042000000003 -0.0001469924999999983" />
      <geometry>
        <box size="0.20786262 0.51781845 0.18883516" />
      </geometry>
    </collision>
  </link>
  <link name="head_link">
    <inertial>
      <origin rpy="0.0 -0.0 0.0" xyz="0.01962 -0.02617 0.00158" />
      <mass value="0.61696" />
      <inertia ixx="0.00217" ixy="-0.00032" ixz="1e-05" iyy="0.0016" iyz="-3e-05" izz="0.00206" />
    </inertial>
    <visual name="">
      <geometry>
        <mesh filename="file:///mnt/nvme1n1p6/PLCT/NAV2/nav2_sim/src/robot_description/meshes/A2_W/head_link.STL"
          scale="1.0 1.0 1.0" />
      </geometry>
      <origin rpy="0.0 -0.0 0.0" xyz="0.0 0.0 0.0" />
      <material name="">
        <color rgba="0.4 1.0 0.4 1.0" />
      </material>
    </visual>
    <collision name="">
      <geometry>
        <box size="0.1024513691663742 0.1386224739253521 0.12076015025377274" />
      </geometry>
      <origin rpy="0.0 -0.0 0.0"
        xyz="0.0028255805373191833 -0.023989001289010048 2.60770320892334e-08" />
    </collision>
  </link>
  
  
  
  <!--- wheels -->
  <joint name="idx01_wheel_joint_1_yaw" type="fixed">
    <parent link="base_link" />
    <child link="wheel_1_yaw" />
    <origin rpy="0.0 -0.0 0.0" xyz="0.24 -0.175 0.0365" />
    <!-- <axis xyz="0.0 0.0 1.0" />
    <limit effort="1000.0" lower="-0.7853" upper="2.3562" velocity="10.0" /> -->
  </joint>
  <joint name="idx02_wheel_joint_1" type="continuous">
    <parent link="wheel_1_yaw" />
    <child link="wheel_1" />
    <origin rpy="-1.570796 -0.0 0.0" xyz="0.0 0.0 0.0" />
    <axis xyz="0 0 1" />
    <!-- <axis xyz="0.0 0.0 1.0" /> -->
    <!-- <limit effort="1000.0" lower="-3.14" upper="3.14" velocity="10.0" /> -->
  </joint>
  
  
  <joint name="idx03_wheel_joint_2_yaw" type="fixed">
    <parent link="base_link" />
    <child link="wheel_2_yaw" />
    <origin rpy="0.0 -0.0 0.0" xyz="-0.24 -0.175 0.0365" />
    <!-- <axis xyz="0.0 0.0 1.0" />
    <limit effort="1000.0" lower="-2.3562" upper="0.7853" velocity="10.0" /> -->
  </joint>
  <joint name="idx04_wheel_joint_2" type="continuous">
    <parent link="wheel_2_yaw" />
    <child link="wheel_2" />
    <origin rpy="-1.570796 -0.0 0.0" xyz="-0.01037 0.0 0.0" />
    <axis xyz="0 0 1" />
    <!-- <axis xyz="0.0 0.0 1.0" />
    <limit effort="1000.0" lower="-3.14" upper="3.14" velocity="10.0" /> -->
  </joint>
  
  
  <joint name="idx05_wheel_joint_3_yaw" type="fixed">
    <parent link="base_link" />
    <child link="wheel_3_yaw" />
    <origin rpy="0.0 -0.0 0.0" xyz="-0.24 0.175 0.0365" />
    <!-- <axis xyz="0.0 0.0 1.0" />
    <limit effort="1000.0" lower="-0.7853" upper="2.3562" velocity="10.0" /> -->
  </joint>
  <joint name="idx06_wheel_joint_3" type="continuous">
    <parent link="wheel_3_yaw" />
    <child link="wheel_3" />
    <origin rpy="1.570796 -0.0 0.0" xyz="-0.01037 0.0 0.0" />
    <axis xyz="0 0 -1" />
    <!-- <axis xyz="0.0 0.0 -1.0" />
    <limit effort="1000.0" lower="-3.14" upper="3.14" velocity="10.0" /> -->
  </joint>
  
  
  <joint name="idx07_wheel_joint_4_yaw" type="fixed">
    <parent link="base_link" />
    <child link="wheel_4_yaw" />
    <origin rpy="0.0 -0.0 3.14159265" xyz="0.24 0.175 0.0365" />
    <!-- <axis xyz="0.0 0.0 1.0" />
    <limit effort="1000.0" lower="-2.3562" upper="0.7853" velocity="10.0" /> -->
  </joint>
  <joint name="idx08_wheel_joint_4" type="continuous">
    <parent link="wheel_4_yaw" />
    <child link="wheel_4" />
    <origin rpy="-1.570796 -0.0 0.0" xyz="0.0 0.0 0.0" />
    <axis xyz="0 0 -1" />
    <!-- <axis xyz="0.0 0.0 -1.0" />
    <limit effort="1000.0" lower="-3.14" upper="3.14" velocity="10.0" /> -->
  </joint>
  
  
   <gazebo>
    <plugin name='diff_drive' filename='libgazebo_ros_diff_drive.so'>
      <ros>
        <namespace>/</namespace>
      </ros>

      <!-- Number of wheel pairs -->
      <num_wheel_pairs>2</num_wheel_pairs>

      <!-- wheels -->
      <left_joint>idx02_wheel_joint_1</left_joint>
      <right_joint>idx08_wheel_joint_4</right_joint>
      <left_joint>idx04_wheel_joint_2</left_joint>
      <right_joint>idx06_wheel_joint_3</right_joint>
      
      <!-- kinematics -->
      <wheel_separation>0.35</wheel_separation>
      <wheel_separation>0.35</wheel_separation>
      <wheel_diameter>0.15</wheel_diameter>
      <wheel_diameter>0.15</wheel_diameter>


      <!-- limits -->
      <max_wheel_torque>50.0</max_wheel_torque>
      <max_wheel_acceleration>8.0</max_wheel_acceleration>
      <max_angular_velocity>8.0</max_angular_velocity> 

      <!-- output -->
      <publish_odom>true</publish_odom>
      <publish_odom_tf>true</publish_odom_tf>
      <publish_wheel_tf>true</publish_wheel_tf>
      <odometry_frame>odom</odometry_frame>
      <robot_base_frame>base_link</robot_base_frame>
    </plugin>

  </gazebo>





  <joint name="idx09_lift_joint" type="prismatic">
    <parent link="base_link" />
    <child link="body_link1" />
    <origin rpy="0.0 -0.0 0.0" xyz="-0.039 0.0 0.8375" />
    <axis xyz="0.0 0.0 1.0" />
    <limit effort="1000.0" lower="-0.285" upper="0.285" velocity="0.5" />
  </joint>
  <joint name="idx10_waist_joint" type="fixed">
    <parent link="body_link1" />
    <child link="body_link2" />
    <origin rpy="-1.5707963 -0.0 0.0" xyz="0.1395 0.0 0.015" />
    <axis xyz="0.0 0.0 1.0" />
    <limit effort="1000.0" lower="0.0" upper="2.3562" velocity="0.785398" />
  </joint>
  <joint name="idx11_head_joint" type="revolute">
    <parent link="arm_base_link" />
    <child link="head_link" />
    <origin rpy="-1.5707963267948966 -0.0 0.0" xyz="0.066 0.0 0.3465" />
    <axis xyz="0.0 0.0 1.0" />
    <limit effort="1000.0" lower="-1.13446" upper="1.13446" velocity="10.0" />
  </joint>
  <!-- left and right arms links and joints-->
  <joint name="arm_base_joint" type="fixed">
    <parent link="body_link2" />
    <child link="arm_base_link" />
    <origin rpy="1.5707963267948966 0 0" xyz="0 -0.1 0" />
    <axis xyz="1 0 0" />
  </joint>
  <link name="arm_base_link">
    <visual name="">
      <geometry>
        <mesh filename="file:///mnt/nvme1n1p6/PLCT/NAV2/nav2_sim/src/robot_description/meshes/A2_W/arm_base_link.STL" />
      </geometry>
      <origin rpy="0.0 0.0 0.0" xyz="0.0 0.0 0.0" />
      <material name="">
        <color rgba="1.0 0.2 0.0 1.0" />
        <texture filename="" />
      </material>
      <collision>
      </collision>
    </visual>
    <collision>
      <origin rpy="-0.0 0.0 -0.0" xyz="0.0 0.0 0.22053301" />
      <geometry>
        <box size="0.16 0.27200043 0.12292724999999999" />
      </geometry>
    </collision>
  </link>
  <joint name="left_arm_base_joint" type="fixed">
    <parent link="arm_base_link" />
    <child link="left_arm_link_base" />
    <origin rpy="1.5707963267948966 0 3.141592653589793" xyz="0 0.016 0.22" />
    <axis xyz="1 0 0" />
  </joint>
  <link name="left_arm_link_base" />
  <joint name="idx12_left_arm_joint1" type="revolute">
    <parent link="left_arm_link_base" />
    <child link="left_arm_link01" />
    <origin rpy="0 0 0" xyz="0 0 0" />
    <axis xyz="0 0 1" />
    <limit effort="0" lower="-6.283185307" upper="6.283185307" velocity="1.57079633" />
  </joint>
  <link name="left_arm_link01">
    <inertial>
      <origin rpy="0.0 -0.0 0.0"
        xyz="-0.000292150224881238 -1.12810757324664e-07 -0.0197883159042773" />
      <mass value="2.02385782634915" />
      <inertia ixx="0.00327452681763125" ixy="3.17383618730096e-10" ixz="-1.44572790349294e-05"
        iyy="0.00393874762963898" iyz="-7.40816403457167e-09" izz="0.00228536491357114" />
    </inertial>
    <visual name="">
      <geometry>
        <mesh filename="file:///mnt/nvme1n1p6/PLCT/NAV2/nav2_sim/src/robot_description/meshes/A2_W/l1.STL" />
      </geometry>
      <origin rpy="0.0 -0.0 0.0" xyz="0.0 0.0 0.0" />
      <material name="">
        <color rgba="1.0 0.4 0.4 1.0" />
        <texture filename="" />
      </material>
    </visual>
    <collision name="">
      <geometry>
        <cylinder length="0.14799022674560547" radius="0.0522" />
      </geometry>
      <origin rpy="0.0 -0.0 0.0"
        xyz="-4.0978193283081055e-08 -4.842877388000488e-08 0.1844952404499054" />
    </collision>
  </link>
  <joint name="idx13_left_arm_joint2" type="revolute">
    <parent link="left_arm_link01" />
    <child link="left_arm_link02" />
    <origin rpy="-1.5707963267948966 0 0" xyz="0.0 0 0.21" />
    <axis xyz="0 0 1" />
    <limit effort="0.0" lower="-1.8325" upper="1.8325" velocity="1.57079633" />
  </joint>
  <link name="left_arm_link02">
    <inertial>
      <origin rpy="0.0 -0.0 0.0"
        xyz="-0.000764732971055488 0.0463677706375549 -1.08299137438191e-06" />
      <mass value="3.07776518847488" />
      <inertia ixx="0.0106872446899394" ixy="-6.21551008934875e-06" ixz="-5.96904750289585e-07"
        iyy="0.00620159070813758" iyz="1.58544664743531e-07" izz="0.00869648011399527" />
    </inertial>
    <visual name="">
      <geometry>
        <mesh filename="file:///mnt/nvme1n1p6/PLCT/NAV2/nav2_sim/src/robot_description/meshes/A2_W/l2.STL" />
      </geometry>
      <origin rpy="0.0 -0.0 0.0" xyz="0.0 0.0 0.0" />
      <material name="">
        <color rgba="1.0 1.0 0.4 1.0" />
        <texture filename="" />
      </material>
    </visual>
    <collision name="">
      <geometry>
        <box size="0.10358428955078125 0.17078391090035439 0.12926186621189117" />
      </geometry>
      <origin rpy="0.0 -0.0 0.0"
        xyz="-3.725290298461914e-08 -0.034391483291983604 -2.7567148208618164e-07" />
    </collision>
  </link>
  <joint name="idx14_left_arm_joint3" type="revolute">
    <parent link="left_arm_link02" />
    <child link="left_arm_link03" />
    <origin rpy="1.5707963267948966 0 0" xyz="0.0 0 0.0" />
    <axis xyz="0 0 1" />
    <limit effort="0.0" lower="-6.283185307" upper="6.283185307" velocity="1.57079633" />
  </joint>
  <link name="left_arm_link03">
    <inertial>
      <origin rpy="0.0 -0.0 0.0" xyz="-0.00824138330670573 1.81304505288539e-06 -0.0994389593831141" />
      <mass value="1.27512614281375" />
      <inertia ixx="0.00678262221603033" ixy="5.87422379695598e-08" ixz="0.000127149961199075"
        iyy="0.00672632884309339" iyz="-2.63248536989187e-08" izz="0.00137287952544927" />
    </inertial>
    <visual name="">
      <geometry>
        <mesh filename="file:///mnt/nvme1n1p6/PLCT/NAV2/nav2_sim/src/robot_description/meshes/A2_W/l3.STL" />
      </geometry>
      <origin rpy="0.0 -0.0 0.0" xyz="0.0 0.0 0.0" />
      <material name="">
        <color rgba="0.4 1.0 0.4 1.0" />
        <texture filename="" />
      </material>
    </visual>
    <collision>
      <origin rpy="-0.0 0.0 -0.0" xyz="-0.0003997758000000018 0.00041143970000000196 0.22642349" />
      <geometry>
        <box size="0.10300003 0.1029582 0.21228018000000004" />
      </geometry>
    </collision>
  </link>
  <joint name="idx15_left_arm_joint4" type="revolute">
    <parent link="left_arm_link03" />
    <child link="left_arm_link04" />
    <origin rpy="-1.5707963267948966 0 0" xyz="0.0 0 0.3285" />
    <axis xyz="0 0 1" />
    <limit effort="0.0" lower="-2.5307" upper="0.5235" velocity="1.04719755" />
  </joint>
  <link name="left_arm_link04">
    <inertial>
      <origin rpy="0.0 -0.0 0.0" xyz="0.00470891029062593 -0.0462958709335049 1.46218467922399e-06" />
      <mass value="1.71924475649685" />
      <inertia ixx="0.0043885572143936" ixy="7.21415529116022e-05" ixz="-3.19786042087572e-09"
        iyy="0.00212591691336027" iyz="1.62718576482481e-07" izz="0.0037667887997095" />
    </inertial>
    <visual name="">
      <geometry>
        <mesh filename="file:///mnt/nvme1n1p6/PLCT/NAV2/nav2_sim/src/robot_description/meshes/A2_W/l4.STL" />
      </geometry>
      <origin rpy="0.0 -0.0 0.0" xyz="0.0 0.0 0.0" />
      <material name="">
        <color rgba="0.4 1.0 1.0 1.0" />
        <texture filename="" />
      </material>
    </visual>
    <collision>
      <origin rpy="-0.0 0.0 -0.0"
        xyz="0.00020905025000000216 -0.0005835909400000033 0.0004010144600000015" />
      <geometry>
        <cylinder length=".10766125" radius="0.048" />
      </geometry>
    </collision>
    <collision>
      <origin rpy="-0.0 0.0 -0.0" xyz="0.00020905025000000216 -0.04648283 0.0004010144600000015" />
      <geometry>
        <box size="0.09023327 0.12190476 0.10766125" />
      </geometry>
    </collision>
  </link>
  <joint name="idx16_left_arm_joint5" type="revolute">
    <parent link="left_arm_link04" />
    <child link="left_arm_link05" />
    <origin rpy="1.5707963267948966 0 0" xyz="0.0 0 0.0" />
    <axis xyz="0 0 1" />
    <limit effort="0.0" lower="-6.283185307" upper="6.283185307" velocity="1.30899694" />
  </joint>
  <link name="left_arm_link05">
    <inertial>
      <origin rpy="0.0 -0.0 0.0"
        xyz="-6.05301320542687e-07 -0.00246464881032554 -0.0478087262212615" />
      <mass value="0.738963959605227" />
      <inertia ixx="0.00150596128432571" ixy="-4.84746742299547e-08" ixz="2.030038956901e-08"
        iyy="0.00151705641849838" iyz="7.66360309564245e-05" izz="0.000640175137684413" />
    </inertial>
    <visual name="">
      <geometry>
        <mesh filename="file:///mnt/nvme1n1p6/PLCT/NAV2/nav2_sim/src/robot_description/meshes/A2_W/l5.STL" />
      </geometry>
      <origin rpy="0.0 -0.0 0.0" xyz="0.0 0.0 0.0" />
      <material name="">
        <color rgba="0.0 0.5 1.0 1.0" />
        <texture filename="" />
      </material>
    </visual>
    <collision name="">
      <geometry>
        <box size="0.08318585157394409 0.0841069221496582 0.16509421914815903" />
      </geometry>
      <origin rpy="0.0 -0.0 0.0"
        xyz="1.1175870895385742e-08 -0.0004452727735042572 0.19048230722546577" />
    </collision>
  </link>
  <joint name="idx17_left_arm_joint6" type="revolute">
    <parent link="left_arm_link05" />
    <child link="left_arm_link06" />
    <origin rpy="-1.5707963267948966 0 0" xyz="0.0 0 0.23500000000000001" />
    <axis xyz="0 0 1" />
    <limit effort="0.0" lower="-1.8325" upper="1.8325" velocity="1.30899694" />
  </joint>
  <link name="left_arm_link06">
    <inertial>
      <origin rpy="0.0 -0.0 0.0" xyz="1.35352348208136e-06 0.0125905423256474 0.02068447894616" />
      <mass value="0.302827567199497" />
      <inertia ixx="0.000250252928330785" ixy="3.29952287452313e-09" ixz="4.78747269554221e-09"
        iyy="0.000224533313113618" iyz="6.9192354881762e-05" izz="0.000273195785421702" />
    </inertial>
    <visual name="">
      <geometry>
        <mesh filename="file:///mnt/nvme1n1p6/PLCT/NAV2/nav2_sim/src/robot_description/meshes/A2_W/l6.STL" />
      </geometry>
      <origin rpy="0.0 -0.0 0.0" xyz="0.0 0.0 0.0" />
      <material name="">
        <color rgba="0.3 0.5 1.0 1.0" />
        <texture filename="" />
      </material>
    </visual>
    <collision name="">
      <geometry>
        <box size="0.08100000023841858 0.19017678871750832 0.08721351623535156" />
      </geometry>
      <origin rpy="0.0 -0.0 0.0" xyz="0.0 -0.05858358554542065 0.0031057745218276978" />
    </collision>
  </link>
  <joint name="left_arm_joint7" type="fixed">
    <parent link="left_arm_link06" />
    <child link="left_arm_link07_transition" />
    <origin rpy="1.5707963267948966 0 0" xyz="0.0 0 0.0" />
    <axis xyz="1.0 0.0 0.0" />
  </joint>
  <link name="left_arm_link07_transition">
    <visual name="">
      <geometry>
        <mesh filename="file:///mnt/nvme1n1p6/PLCT/NAV2/nav2_sim/src/robot_description/meshes/A2_W/l7.STL" />
      </geometry>
      <origin rpy="0.0 -0.0 0.0" xyz="0.0 0.0 0.0" />
      <material name="">
        <color rgba="1.0 0.5 1.0 1.0" />
        <texture filename="" />
      </material>
    </visual>
    <collision name="">
      <geometry>
        <cylinder length="0.0495000034570694" radius="0.040500002409446435" />
      </geometry>
      <origin rpy="0.0 -0.0 -0.6283185307179586"
        xyz="2.6941458824645297e-07 -8.132760131849638e-07 0.1784219816327095" />
    </collision>
  </link>
  <joint name="idx18_left_arm_joint7" type="revolute">
    <parent link="left_arm_link07_transition" />
    <child link="left_arm_link07" />
    <origin rpy="0.0 0 0" xyz="0.0 0 0.2031999969482422" />
    <axis xyz="0 0 1" />
    <limit effort="0.0" lower="-6.283185307" upper="6.283185307" velocity="1.30899694" />
  </joint>
  <link name="left_arm_link07">
    <inertial>
      <origin rpy="0.0 -0.0 0.0"
        xyz="-7.34070725421397e-18 -0.000409941998595975 0.0893466206824696" />
      <mass value="1.15179107216279" />
      <inertia ixx="0.00130138175950958" ixy="1.16212181945625e-20" ixz="4.05921705278271e-20"
        iyy="0.00130166815098701" iyz="5.57134965987214e-07" izz="0.000798504547777817" />
    </inertial>
  </link>
  <joint name="left_finger_base_joint" type="fixed">
    <parent link="left_arm_link07" />
    <child link="left_finger_base" />
    <origin rpy="0.0 -0.0 1.570796326" xyz="0.0 0.0 0.0" />
    <axis xyz="1.0 0.0 0.0" />
  </joint>
  <link name="left_finger_base">
    <visual name="">
      <geometry>
        <mesh filename="file:///mnt/nvme1n1p6/PLCT/NAV2/nav2_sim/src/robot_description/meshes/A2_W/finger_base.STL"
          scale="0.001 0.001 0.001" />
      </geometry>
      <origin rpy="0.0 -0.0 0.0" xyz="0.0 0.0 0.0" />
      <material name="">
        <color rgba="1.0 1.0 0.0 1.0" />
        <texture filename="" />
      </material>
    </visual>
    <collision>
      <origin rpy="-0.0 0.0 -0.0" xyz="0.0 1.0844320000001628e-05 0.058920860000000005" />
      <geometry>
        <box size="0.0987854 0.10564122 0.13784218" />
      </geometry>
    </collision>
    <collision>
      <origin rpy="-0.0 0.0 -0.0" xyz="0.06499481 4.499964399999959e-05 0.003749847399999999" />
      <geometry>
        <box size="0.06199646 0.06209 0.06850052" />
      </geometry>
    </collision>
  </link>
  <joint name="left_finger_left_joint" type="fixed">
    <parent link="left_finger_base" />
    <child link="left_finger_left" />
    <origin rpy="0.0 -0.0 0.0" xyz="0.0 0.025 0.17784" />
    <axis xyz="0.0 -1.0 0.0" />
    <limit effort="1000.0" lower="0.0" upper="0.025" velocity="10.0" />
  </joint>
  <link name="left_finger_left">
    <visual name="">
      <geometry>
        <mesh filename="file:///mnt/nvme1n1p6/PLCT/NAV2/nav2_sim/src/robot_description/meshes/A2_W/finger.STL"
          scale="0.001 0.001 0.001" />
      </geometry>
      <origin rpy="0.0 -0.0 0.0" xyz="0.0 0.0 0.0" />
      <material name="">
        <color rgba="1.0 0.2 0.0 1.0" />
        <texture filename="" />
      </material>
    </visual>
    <collision>
      <origin rpy="-0.0 0.0 -0.0" xyz="0.008056641 0.009464729999999998 -0.040039062" />
      <geometry>
        <box size="0.04345703 0.02092956 0.107421875" />
      </geometry>
    </collision>
  </link>
  <joint name="left_finger_right_joint" type="fixed">
    <parent link="left_finger_base" />
    <child link="left_finger_right" />
    <origin rpy="0.0 -0.0 3.141592653" xyz="0.0 -0.025 0.17784" />
    <axis xyz="0.0 -1.0 0.0" />
    <limit effort="1000.0" lower="0.0" upper="0.025" velocity="10.0" />
  </joint>
  <link name="left_finger_right">
    <visual name="">
      <geometry>
        <mesh filename="file:///mnt/nvme1n1p6/PLCT/NAV2/nav2_sim/src/robot_description/meshes/A2_W/finger.STL"
          scale="0.001 0.001 0.001" />
      </geometry>
      <origin rpy="0.0 -0.0 0.0" xyz="0.0 0.0 0.0" />
      <material name="">
        <color rgba="1.0 0.2 0.0 1.0" />
        <texture filename="" />
      </material>
    </visual>
    <collision>
      <origin rpy="-0.0 0.0 -0.0" xyz="0.008056641 0.009464729999999998 -0.040039062" />
      <geometry>
        <box size="0.04345703 0.02092956 0.107421875" />
      </geometry>
    </collision>
  </link>
  <joint name="right_arm_base_joint" type="fixed">
    <parent link="arm_base_link" />
    <child link="right_arm_link_base" />
    <origin rpy="1.5707963267948966 0 0" xyz="0.0 -0.016 0.22" />
    <axis xyz="1.0 0.0 0.0" />
  </joint>
  <link name="right_arm_link_base" />
  <joint name="idx19_right_arm_joint1" type="revolute">
    <parent link="right_arm_link_base" />
    <child link="right_arm_link01" />
    <origin rpy="0 0 3.141592653589793" xyz="0 0 0" />
    <axis xyz="0 0 1" />
    <limit effort="0.0" lower="-6.283185307" upper="6.283185307" velocity="1.57079633" />
  </joint>
  <link name="right_arm_link01">
    <inertial>
      <origin rpy="0.0 -0.0 0.0" xyz="0.000291913014515816 1.12991503370284e-07 -0.0197875585293091" />
      <mass value="2.02380742891555" />
      <inertia ixx="0.00327445532699987" ixy="3.06951274044252e-10" ixz="1.44409399202843e-05"
        iyy="0.00393863523048524" iyz="7.4219175788952e-09" izz="0.00228528256199511" />
    </inertial>
    <visual name="">
      <geometry>
        <mesh filename="file:///mnt/nvme1n1p6/PLCT/NAV2/nav2_sim/src/robot_description/meshes/A2_W/r1.STL" />
      </geometry>
      <origin rpy="0.0 -0.0 0.0" xyz="0.0 0.0 0.0" />
      <material name="">
        <color rgba="1.0 0.4 0.4 1.0" />
        <texture filename="" />
      </material>
    </visual>
    <collision name="">
      <geometry>
        <cylinder length="0.14799022674560547" radius="0.0522" />
      </geometry>
      <origin rpy="0.0 -0.0 0.0"
        xyz="-4.0978193283081055e-08 -4.842877388000488e-08 0.1844952404499054" />
    </collision>
  </link>
  <joint name="idx20_right_arm_joint2" type="revolute">
    <parent link="right_arm_link01" />
    <child link="right_arm_link02" />
    <origin rpy="-1.5707963267948966 0 0" xyz="0.0 0 0.21" />
    <axis xyz="0 0 1" />
    <limit effort="0.0" lower="-1.8325" upper="1.8325" velocity="1.57079633" />
  </joint>
  <link name="right_arm_link02">
    <inertial>
      <origin rpy="0.0 -0.0 0.0" xyz="0.000764732971055497 -0.046367770637555 -1.0829913744076e-06" />
      <mass value="3.07776518847489" />
      <inertia ixx="0.0106872446899394" ixy="-6.2155100893485e-06" ixz="5.96904750290664e-07"
        iyy="0.00620159070813759" iyz="-1.58544664742331e-07" izz="0.00869648011399528" />
    </inertial>
    <visual name="">
      <geometry>
        <mesh filename="file:///mnt/nvme1n1p6/PLCT/NAV2/nav2_sim/src/robot_description/meshes/A2_W/r2.STL" />
      </geometry>
      <origin rpy="0.0 -0.0 0.0" xyz="0.0 0.0 0.0" />
      <material name="">
        <color rgba="1.0 1.0 0.4 1.0" />
        <texture filename="" />
      </material>
    </visual>
    <collision name="">
      <geometry>
        <box size="0.10358428955078125 0.17078391090035439 0.12926186621189117" />
      </geometry>
      <origin rpy="0.0 -0.0 0.0"
        xyz="3.725290298461914e-08 -0.034391483291983604 -6.258487701416016e-07" />
    </collision>
  </link>
  <joint name="idx21_right_arm_joint3" type="revolute">
    <parent link="right_arm_link02" />
    <child link="right_arm_link03" />
    <origin rpy="1.5707963267948966 0 0" xyz="0.0 0 0.0" />
    <axis xyz="0.0 0.0 1.0" />
    <limit effort="0.0" lower="-6.283185307" upper="6.283185307" velocity="1.57079633" />
  </joint>
  <link name="right_arm_link03">
    <inertial>
      <origin rpy="0.0 -0.0 0.0" xyz="0.00824162301579328 -1.8165528872789e-06 -0.0994389659977605" />
      <mass value="1.27512614281375" />
      <inertia ixx="0.00678262146366617" ixy="5.86606221599747e-08" ixz="-0.00012715011253676"
        iyy="0.0067263282560404" iyz="2.66529371138895e-08" izz="0.00137287938477962" />
    </inertial>
    <visual name="">
      <geometry>
        <mesh filename="file:///mnt/nvme1n1p6/PLCT/NAV2/nav2_sim/src/robot_description/meshes/A2_W/r3.STL" />
      </geometry>
      <origin rpy="0.0 -0.0 0.0" xyz="0.0 0.0 0.0" />
      <material name="">
        <color rgba="0.4 1.0 0.4 1.0" />
        <texture filename="" />
      </material>
    </visual>
    <collision>
      <origin rpy="-0.0 0.0 -0.0" xyz="-0.0003997758000000018 0.00041143970000000196 0.22642349" />
      <geometry>
        <box size="0.10300003 0.1029582 0.21228018000000004" />
      </geometry>
    </collision>
  </link>
  <joint name="idx22_right_arm_joint4" type="revolute">
    <parent link="right_arm_link03" />
    <child link="right_arm_link04" />
    <origin rpy="-1.5707963267948966 0 0" xyz="0.0 0 0.3285" />
    <axis xyz="0.0 0.0 1.0" />
    <limit effort="0.0" lower="-2.5307" upper="0.5235" velocity="1.04719755" />
  </joint>
  <link name="right_arm_link04">
    <inertial>
      <origin rpy="0.0 -0.0 0.0" xyz="0.00470891029062579 -0.046295870933505 1.46218467916839e-06" />
      <mass value="1.71924475649685" />
      <inertia ixx="0.00438846170466841" ixy="-7.21270944018646e-05" ixz="-1.43545932326502e-09"
        iyy="0.00212587329761589" iyz="-1.69073887466953e-07" izz="0.00376671975131459" />
    </inertial>
    <visual name="">
      <geometry>
        <mesh filename="file:///mnt/nvme1n1p6/PLCT/NAV2/nav2_sim/src/robot_description/meshes/A2_W/r4.STL" />
      </geometry>
      <origin rpy="0.0 -0.0 0.0" xyz="0.0 0.0 0.0" />
      <material name="">
        <color rgba="0.4 1.0 1.0 1.0" />
        <texture filename="" />
      </material>
    </visual>
    <collision>
      <origin rpy="-0.0 0.0 -0.0"
        xyz="0.00020905025000000216 -0.0005835909400000033 0.0004010144600000015" />
      <geometry>
        <cylinder length="0.10766125" radius="0.048" />
      </geometry>
    </collision>
    <collision>
      <origin rpy="-0.0 0.0 -0.0" xyz="0.00020905025000000216 -0.04648283 0.0004010144600000015" />
      <geometry>
        <box size="0.09023327 0.12190476 0.10766125" />
      </geometry>
    </collision>
  </link>
  <joint name="idx23_right_arm_joint5" type="revolute">
    <parent link="right_arm_link04" />
    <child link="right_arm_link05" />
    <origin rpy="1.5707963267948966 0 0" xyz="0.0 0 0.0" />
    <axis xyz="0.0 0.0 1.0" />
    <limit effort="0.0" lower="-6.283185307" upper="6.283185307" velocity="1.30899694" />
  </joint>
  <link name="right_arm_link05">
    <inertial>
      <origin rpy="0.0 -0.0 0.0"
        xyz="-6.05304372475757e-07 -0.00246464881016278 -0.0478087262315223" />
      <mass value="0.738963958823473" />
      <inertia ixx="0.00150596128506401" ixy="-4.84746524384831e-08" ixz="2.03004207659452e-08"
        iyy="0.00151705641846946" iyz="7.66360310178662e-05" izz="0.000640175136981815" />
    </inertial>
    <visual name="">
      <geometry>
        <mesh filename="file:///mnt/nvme1n1p6/PLCT/NAV2/nav2_sim/src/robot_description/meshes/A2_W/r5.STL" />
      </geometry>
      <origin rpy="0.0 -0.0 0.0" xyz="0.0 0.0 0.0" />
      <material name="">
        <color rgba="0.0 0.5 1.0 1.0" />
        <texture filename="" />
      </material>
    </visual>
    <collision name="">
      <geometry>
        <box size="0.08318585157394409 0.0841069221496582 0.16509421914815903" />
      </geometry>
      <origin rpy="0.0 -0.0 0.0"
        xyz="7.450580596923828e-09 0.0004452727735042572 0.19048230722546577" />
    </collision>
  </link>
  <!-- #### inverse -->
  <joint name="idx24_right_arm_joint6" type="revolute">
    <parent link="right_arm_link05" />
    <child link="right_arm_link06" />
    <origin rpy="-1.5707963267948966 0 3.141592653589793" xyz="-0.0 0 0.23500000000000001" />
    <axis xyz="0.0 0.0 1.0" />
    <limit effort="0.0" lower="-1.8325" upper="1.8325" velocity="1.30899694" />
  </joint>
  <link name="right_arm_link06">
    <inertial>
      <origin rpy="0.0 -0.0 0.0" xyz="1.35352348211284e-06 0.0125905423256473 0.0206844789461601" />
      <mass value="0.302827567199493" />
      <inertia ixx="0.000250252928330784" ixy="3.29952287446685e-09" ixz="4.78747269554272e-09"
        iyy="0.000224533313113614" iyz="6.9192354881762e-05" izz="0.000273195785421698" />
    </inertial>
    <visual name="">
      <geometry>
        <mesh filename="file:///mnt/nvme1n1p6/PLCT/NAV2/nav2_sim/src/robot_description/meshes/A2_W/r6.STL" />
      </geometry>
      <origin rpy="0.0 -0.0 0.0" xyz="0.0 0.0 0.0" />
      <material name="">
        <color rgba="0.3 0.5 1.0 1.0" />
        <texture filename="" />
      </material>
    </visual>
    <collision name="">
      <geometry>
        <box size="0.08100000023841858 0.19017678871750832 0.08721351623535156" />
      </geometry>
      <origin rpy="0.0 -0.0 0.0" xyz="0.0 -0.05858358554542065 0.0031083300709724426" />
    </collision>
  </link>
  <joint name="right_arm_joint7" type="fixed">
    <parent link="right_arm_link06" />
    <child link="right_arm_link07_transition" />
    <origin rpy="1.5707963267948966 0 0" xyz="0.0 0 0.0" />
    <axis xyz="1.0 0.0 0.0" />
  </joint>
  <link name="right_arm_link07_transition">
    <visual name="">
      <geometry>
        <mesh filename="file:///mnt/nvme1n1p6/PLCT/NAV2/nav2_sim/src/robot_description/meshes/A2_W/r7.STL" />
      </geometry>
      <origin rpy="0.0 -0.0 0.0" xyz="0.0 0.0 0.0" />
      <material name="">
        <color rgba="1.0 0.5 1.0 1.0" />
        <texture filename="" />
      </material>
    </visual>
    <collision name="">
      <geometry>
        <cylinder length="0.0495000034570694" radius="0.040500002385802265" />
      </geometry>
      <origin rpy="0.0 -0.0 0.0"
        xyz="2.695302996763571e-07 1.7447452578603362e-06 0.1784219816327095" />
    </collision>
  </link>
  <joint name="idx25_right_arm_joint7" type="revolute">
    <parent link="right_arm_link07_transition" />
    <child link="right_arm_link07" />
    <origin rpy="0.0 0 0" xyz="0.0 0 0.2031999969482422" />
    <axis xyz="0.0 0.0 1.0" />
    <limit effort="0.0" lower="-6.283185307" upper="6.283185307" velocity="1.30899694" />
  </joint>
  <link name="right_arm_link07">
    <inertial>
      <origin rpy="0.0 -0.0 0.0"
        xyz="-3.79163692585331e-18 -0.000409941998596018 0.0893466206824701" />
      <mass value="1.15179107216279" />
      <inertia ixx="0.00130138175950958" ixy="-3.40812510041493e-20" ixz="-3.37408342676276e-20"
        iyy="0.00130166815098701" iyz="5.57134965987262e-07" izz="0.000798504547777817" />
    </inertial>
  </link>
  <joint name="right_finger_base_joint" type="fixed">
    <parent link="right_arm_link07" />
    <child link="right_finger_base" />
    <origin rpy="0.0 -0.0 1.570796326" xyz="0.0 0.0 0.0" />
    <axis xyz="1.0 0.0 0.0" />
  </joint>
  <link name="right_finger_base">
    <visual name="">
      <geometry>
        <mesh filename="file:///mnt/nvme1n1p6/PLCT/NAV2/nav2_sim/src/robot_description/meshes/A2_W/finger_base.STL"
          scale="0.001 0.001 0.001" />
      </geometry>
      <origin rpy="0.0 -0.0 0.0" xyz="0.0 0.0 0.0" />
      <material name="">
        <color rgba="1.0 1.0 0.0 1.0" />
        <texture filename="" />
      </material>
    </visual>
    <collision>
      <origin rpy="-0.0 0.0 -0.0" xyz="0.0 1.0844320000001628e-05 0.058920860000000005" />
      <geometry>
        <box size="0.0987854 0.10564122 0.13784218" />
      </geometry>
    </collision>
    <collision>
      <origin rpy="-0.0 0.0 -0.0" xyz="0.06499481 4.499964399999959e-05 0.003749847399999999" />
      <geometry>
        <box size="0.06199646 0.06209 0.06850052" />
      </geometry>
    </collision>
  </link>
  <joint name="right_finger_left_joint" type="fixed">
    <parent link="right_finger_base" />
    <child link="right_finger_left" />
    <origin rpy="0.0 -0.0 0.0" xyz="0.0 0.025 0.17784" />
    <axis xyz="0.0 -1.0 0.0" />
    <limit effort="1000.0" lower="0.0" upper="0.025" velocity="10.0" />
  </joint>
  <link name="right_finger_left">
    <visual name="">
      <geometry>
        <mesh filename="file:///mnt/nvme1n1p6/PLCT/NAV2/nav2_sim/src/robot_description/meshes/A2_W/finger.STL"
          scale="0.001 0.001 0.001" />
      </geometry>
      <origin rpy="0.0 -0.0 0.0" xyz="0.0 0.0 0.0" />
      <material name="">
        <color rgba="1.0 0.2 0.0 1.0" />
        <texture filename="" />
      </material>
    </visual>
    <collision>
      <origin rpy="-0.0 0.0 -0.0" xyz="0.008056641 0.009464729999999998 -0.040039062" />
      <geometry>
        <box size="0.04345703 0.02092956 0.107421875" />
      </geometry>
    </collision>
  </link>
  <joint name="right_finger_right_joint" type="fixed">
    <parent link="right_finger_base" />
    <child link="right_finger_right" />
    <origin rpy="0.0 -0.0 3.141592653" xyz="0.0 -0.025 0.17784" />
    <axis xyz="0.0 -1.0 0.0" />
    <limit effort="1000.0" lower="0.0" upper="0.025" velocity="10.0" />
  </joint>
  <link name="right_finger_right">
    <visual name="">
      <geometry>
        <mesh filename="file:///mnt/nvme1n1p6/PLCT/NAV2/nav2_sim/src/robot_description/meshes/A2_W/finger.STL"
          scale="0.001 0.001 0.001" />
      </geometry>
      <origin rpy="0.0 -0.0 0.0" xyz="0.0 0.0 0.0" />
      <material name="">
        <color rgba="1.0 0.2 0.0 1.0" />
        <texture filename="" />
      </material>
    </visual>
    <collision>
      <origin rpy="-0.0 0.0 -0.0" xyz="0.008056641 0.009464729999999998 -0.040039062" />
      <geometry>
        <box size="0.04345703 0.02092956 0.107421875" />
      </geometry>
    </collision>
  </link>
  <!-- sensor links and joints-->
  <joint name="lidar3D_top_joint" type="fixed">
    <parent link="base_link" />
    <child link="lidar3D_top" />
    <origin rpy="3.141592653589793 0.0 0.0" xyz="-0.071 0 1.47215" />
    <axis xyz="1 0 0" />
  </joint>
  <link name="lidar3D_top" />
  <joint name="lidar2D_base_joint" type="fixed">
    <parent link="base_link" />
    <child link="lidar2D_base" />
    <origin rpy="0.0 0.0 0.0" xyz="0.2565 0.0 0.263" />
    <axis xyz="1 0 0" />
  </joint>
  <link name="lidar2D_base" />
  <joint name="rgbd_base_front_joint" type="fixed">
    <parent link="base_link" />
    <child link="rgbd_base_front" />
    <origin rpy="-1.57079633 0.0 -1.57079633" xyz="0.35318 0 0.2005" />
    <axis xyz="1 0 0" />
  </joint>
  <link name="rgbd_base_front" />
  
  <gazebo reference="lidar3D_top">
    <sensor name="lidar" type="ray">
      <always_on>true</always_on>
      <visualize>true</visualize>
      <update_rate>5</update_rate>
      <ray>
        <scan>
          <horizontal>
            <samples>360</samples>
            <resolution>1.000000</resolution>
            <min_angle>-0.7850000</min_angle>
            <max_angle>0.7850000</max_angle>
          </horizontal>
        </scan>

        <range>
          <min>0.120000</min>
          <max>3.5</max>
          <resolution>0.015000</resolution>
        </range>

        <noise>
          <type>gaussian</type>
          <mean>0.0</mean>
          <stddev>0.01</stddev>
        </noise>
      </ray>

      <plugin name="scan" filename="libgazebo_ros_ray_sensor.so">
        <ros>
          <remapping>~/out:=scan</remapping>
        </ros>

        <output_type>sensor_msgs/LaserScan</output_type>
        <frame_name>lidar3D_top</frame_name>
      </plugin>
    </sensor>
  </gazebo>
  
  
  
  <!-- 
    <joint name="fisheye_back_left_joint" type="fixed">
      <parent link="base_link"/>
      <child link="fisheye_back_left"/>
      <origin xyz="${fisheye_back_left_xyz[0]} ${fisheye_back_left_xyz[1]} ${fisheye_back_left_xyz[2]}"
  rpy="${fisheye_back_left_rpy[0]} ${fisheye_back_left_rpy[1]} ${fisheye_back_left_rpy[2]}"/>
      <axis xyz="1 0 0"/>
    </joint>
    <link name="fisheye_back_left"/>

    <joint name="fisheye_back_right_joint" type="fixed">
      <parent link="base_link"/>
      <child link="fisheye_back_right"/>
      <origin xyz="${fisheye_back_right_xyz[0]} ${fisheye_back_right_xyz[1]}
  ${fisheye_back_right_xyz[2]}" rpy="${fisheye_back_right_rpy[0]} ${fisheye_back_right_rpy[1]}
  ${fisheye_back_right_rpy[2]}"/>
      <axis xyz="1 0 0"/>
    </joint>
    <link name="fisheye_back_right"/> -->
  <joint name="rgbd_head_joint" type="fixed">
    <parent link="head_link" />
    <child link="rgbd_head" />
    <origin rpy="0.0 1.57079633 0.0" xyz="0.05 -0.0705 0" />
    <axis xyz="1 0 0" />
  </joint>
  <link name="rgbd_head" />
  <joint name="rgbd_hand_left_joint" type="fixed">
    <parent link="left_arm_link07" />
    <child link="rgbd_hand_left" />
    <origin rpy="0.0 -0.0 3.141592653589793" xyz="0.0 0.065 0.028" />
    <axis xyz="1 0 0" />
  </joint>
  <link name="rgbd_hand_left" />
  <joint name="rgbd_hand_right_joint" type="fixed">
    <parent link="right_arm_link07" />
    <child link="rgbd_hand_right" />
    <origin rpy="0.0 -0.0 3.141592653589793" xyz="0.0 0.065 0.028" />
    <axis xyz="1 0 0" />
  </joint>
  <link name="rgbd_hand_right" />
</robot>